Traceback (most recent call last):
  File "/usr/lib/python3/dist-packages/cryptography/fernet.py", line 119, in _verify_signature
    h.verify(data[-32:])
  File "/usr/lib/python3/dist-packages/cryptography/hazmat/primitives/hmac.py", line 74, in verify
    ctx.verify(signature)
  File "/usr/lib/python3/dist-packages/cryptography/hazmat/backends/openssl/hmac.py", line 75, in verify
    raise InvalidSignature("Signature did not match digest.")
cryptography.exceptions.InvalidSignature: Signature did not match digest.

During handling of the above exception, another exception occurred:

Traceback (most recent call last):
  File "/home/maxwell/Desktop/Decrypt.py", line 29, in <module>
    decrypted_data = decrypt_file(encrypted_file_path, key)
  File "/home/maxwell/Desktop/Decrypt.py", line 15, in decrypt_file
    decrypted_data = fernet.decrypt(encrypted_data)
  File "/usr/lib/python3/dist-packages/cryptography/fernet.py", line 80, in decrypt
    return self._decrypt_data(data, timestamp, time_info)
  File "/usr/lib/python3/dist-packages/cryptography/fernet.py", line 137, in _decrypt_data
    self._verify_signature(data)
  File "/usr/lib/python3/dist-packages/cryptography/fernet.py", line 121, in _verify_signature
    raise InvalidToken
cryptography.fernet.InvalidToken
